Workbook
Name page\x2dtotal: #REF!
Name page\x2dtotal\x2dmaster0: #REF!

Sheet Data_BI
A1: Название | B1: Тип | C1: 2уровень | D1: Ф/Ю | E1: Код валюты | F1: Расшифровка | G1: Сумма | H1: Месяц | I1: Комментарии | J1: УК | K1: Группа
A2: 1) ЧПД | B2: Процентный доход | C2: Проценты по депозиту в ЦБ | D2: Прочее | E2: RUB | F2: ‭Процентные доходы по депозитам в ЦБ РФ‬ | G2: 220656000 | H2: 45658 | J2: Учетные данные | K2: Доход | L2: =(ISNUMBER(G2))-1 -> 0
A3: 2) Комиссии - нетто | B3: Комиссионный расход | C3: Комиссия за переводы | D3: Прочее | E3: RUB | F3: Комиссии в ФФ КЗ | G3: 1.7684847e+08 | H3: 45658 | J3: Управл.Корр | K3: Расход | L3: =(ISNUMBER(G3))-1 -> 0
A4: 3) FX | B4: Безнал | C4: Доход безнал | D4: Прочее | E4: USD | G4: 1.4812088e+08 | H4: 45658 | J4: Учетные данные | K4: Доход | L4: =(ISNUMBER(G4))-1 -> 0
A5: 2) Комиссии - нетто | B5: Комиссионный доход | C5: РКО ФЛ | D5: ФЛ | E5: RUB | F5: ‭Комиссия за расчетное обслуживание ФИЗ. ЛИЦ в рублях‬ | G5: 1.2371387e+08 | H5: 45658 | J5: Учетные данные | K5: Доход | L5: =(ISNUMBER(G5))-1 -> 0
A6: 7) Нетто эффект резервов на ОПУ | B6: Восстановление резервов | C6: =Data_BI!#REF! -> #REF! | D6: Прочее | E6: RUB | F6: ‭РВП по 611-П Восстановление резерва Денежные ср-ва в пути. (47425)‬ | G6: 98348830 | H6: 45658 | J6: Учетные данные | K6: Резервы | L6: =(ISNUMBER(G6))-1 -> 0
A7: 3) FX | B7: Безнал | C7: Доход безнал | D7: Прочее | E7: EUR | G7: 90179795 | H7: 45658 | J7: Учетные данные | K7: Доход | L7: =(ISNUMBER(G7))-1 -> 0
A8: 7) Нетто эффект резервов на ОПУ | B8: Восстановление резервов | C8: =Data_BI!#REF! -> #REF! | D8: Прочее | E8: RUB | F8: ‭РВПС 590-п Доходы от восст.резервов по МБК‬ | G8: 66000000 | H8: 45658 | J8: Учетные данные | K8: Резервы | L8: =(ISNUMBER(G8))-1 -> 0
A9: 3) FX | B9: Безнал | C9: Доход безнал | D9: Прочее | E9: CNY | G9: 51323664 | H9: 45658 | J9: Учетные данные | K9: Доход | L9: =(ISNUMBER(G9))-1 -> 0
A10: 3) FX | B10: Безнал | C10: Доход безнал | D10: Прочее | E10: KZT | G10: 47140831 | H10: 45658 | J10: Учетные данные | K10: Доход | L10: =(ISNUMBER(G10))-1 -> 0
A11: 7) Нетто эффект резервов на ОПУ | B11: Восстановление резервов | C11: =Data_BI!#REF! -> #REF! | D11: Прочее | E11: RUB | F11: ‭Доходы, увеличивающие операционные доходы, на разницу между резервами на возможные потери и оценочными резервами под ожидаемые кредитные убытки‬ | G11: 38300542 | H11: 45658 | J11: Учетные данные | K11: Резервы | L11: =(ISNUMBER(G11))-1 -> 0
A12: 2) Комиссии - нетто | B12: Комиссионный доход | C12: По брокерским счетам | D12: Прочее | E12: RUB | F12: ‭Комиссия по специальным брок. счетам и по операциям клиентов в руб. без НДС (CLIENT)‬ | G12: 37445578 | H12: 45658 | J12: Учетные данные | K12: Доход | L12: =(ISNUMBER(G12))-1 -> 0
A13: 1) ЧПД | B13: Процентный доход | C13: Проценты по ЦБ в портфеле | D13: Прочее | E13: RUB | F13: ‭НКД по облигациям прочих резидентов по АС в рублях‬ | G13: 36920497 | H13: 45658 | J13: Учетные данные | K13: Доход | L13: =(ISNUMBER(G13))-1 -> 0
A14: 1) ЧПД | B14: Процентный доход | C14: Проценты по РЕПО | D14: Прочее | E14: RUB | F14: ‭Доходы от сделок РЕПО в руб.‬ | G14: 36171583 | H14: 45658 | J14: Учетные данные | K14: Доход | L14: =(ISNUMBER(G14))-1 -> 0
A15: 4) ЧТД | B15: Переоценка ЧТД | C15: Доходы от переоценки ЦБ | D15: Прочее | E15: RUB | F15: ‭Положительная переоценка долевых ценных бумаг по ССчП/У прочих резидентов ‬ | G15: 31000000 | H15: 45658 | J15: Учетные данные | K15: Доход | L15: =(ISNUMBER(G15))-1 -> 0
A16: 3) FX | B16: Наличные | C16: Доход налич | D16: Прочее | E16: EUR | G16: 29179361 | H16: 45658 | J16: Учетные данные | K16: Доход | L16: =(ISNUMBER(G16))-1 -> 0
A17: 3) FX | B17: Безнал | C17: Доход безнал | D17: Прочее | E17: USD | G17: 23865668 | H17: 45658 | J17: Учетные данные | K17: Доход | L17: =(ISNUMBER(G17))-1 -> 0
A18: 2) Комиссии - нетто | B18: Комиссионный доход | C18: РКО ЮЛ | D18: ЮЛ | E18: RUB | F18: ‭Комиссия за перевод средств ЮР.ЛИЦ, в руб. без НДС‬ | G18: 20365258 | H18: 45658 | J18: Учетные данные | K18: Доход | L18: =(ISNUMBER(G18))-1 -> 0
A19: 1) ЧПД | B19: Процентный доход | C19: Проценты по ЦБ в портфеле | D19: Прочее | E19: RUB | F19: ‭НКД по облигациям КО по АС в рублях‬ | G19: 17081880 | H19: 45658 | J19: Учетные данные | K19: Доход | L19: =(ISNUMBER(G19))-1 -> 0
A20: 3) FX | B20: Наличные | C20: Доход налич | D20: Прочее | E20: USD | G20: 16957229 | H20: 45658 | J20: Учетные данные | K20: Доход | L20: =(ISNUMBER(G20))-1 -> 0
A21: 1) ЧПД | B21: Процентный доход | C21: Проценты по кредитам ЮЛ/МБК | D21: Прочее | E21: RUB | F21: ‭Процентные доходы по межбанковским кредитам в рублях‬ | G21: 16885068 | H21: 45658 | J21: Учетные данные | K21: Доход | L21: =(ISNUMBER(G21))-1 -> 0
A22: 7) Нетто эффект резервов на ОПУ | B22: Восстановление резервов | C22: =Data_BI!#REF! -> #REF! | D22: Прочее | E22: RUB | F22: ‭РВП по 611-П по остаткам на корсчетах ‬ | G22: 16056714 | H22: 45658 | I22: Согласно ст 292 НК РФ бан имеет право признавать только Резерв поод ссудную задолженность по 590-П | J22: Учетные данные | K22: Резервы | L22: =(ISNUMBER(G22))-1 -> 0
A23: 1) ЧПД | B23: Процентный доход | C23: Проценты по кредитам ЮЛ/МБК | D23: ЮЛ | E23: RUB | F23: ‭Проценты по кредитам предоставл. юр.лицам‬ | G23: 14925084 | H23: 45658 | J23: Учетные данные | K23: Доход | L23: =(ISNUMBER(G23))-1 -> 0
A24: 3) FX | B24: Безнал | C24: Доход безнал | D24: Прочее | E24: KZT | G24: 13740364 | H24: 45658 | J24: Учетные данные | K24: Доход | L24: =(ISNUMBER(G24))-1 -> 0
A25: 2) Комиссии - нетто | B25: Комиссионный доход | C25: РКО ЮЛ | D25: ЮЛ | E25: RUB | F25: ‭Комиссия за доп. услуги ЮР. ЛИЦ (без НДС) в руб.‬ | G25: 13370604 | H25: 45658 | J25: Учетные данные | K25: Доход | L25: =(ISNUMBER(G25))-1 -> 0
A26: 7) Нетто эффект резервов на ОПУ | B26: Восстановление резервов | C26: =Data_BI!$B10 -> Безнал | D26: Прочее | E26: RUB | F26: ‭РВП по 611-П по внутрихозяйственным операциям (счет 60324)‬ | G26: 13264965 | H26: 45658 | I26: Согласно ст 292 НК РФ бан имеет право признавать только Резерв поод ссудную задолженность по 590-П | J26: Учетные данные | K26: Резервы | L26: =(ISNUMBER(G26))-1 -> 0
A27: 3) FX | B27: Безнал | C27: Доход безнал | D27: Прочее | E27: AED | G27: 12068886 | H27: 45658 | J27: Учетные данные | K27: Доход | L27: =(ISNUMBER(G27))-1 -> 0
A28: 3) FX | B28: Безнал | C28: Доход безнал | D28: Прочее | E28: USD | G28: 10073948 | H28: 45658 | J28: Учетные данные | K28: Доход | L28: =(ISNUMBER(G28))-1 -> 0
A29: 2) Комиссии - нетто | B29: Комиссионный доход | C29: РКО ФЛ | D29: ФЛ | E29: RUB | F29: ‭Комиссия за расчетное обслуживание ФИЗ. ЛИЦ в ин.валюте‬ | G29: 9561615.6 | H29: 45658 | J29: Учетные данные | K29: Доход | L29: =(ISNUMBER(G29))-1 -> 0
A30: 1) ЧПД | B30: Процентный доход | C30: Проценты по кредитам ФЛ | D30: ФЛ | E30: RUB | F30: ‭Проценты по кредитм физлиц (срочные)- внутренний‬ | G30: 9451298.9 | H30: 45658 | J30: Учетные данные | K30: Доход | L30: =(ISNUMBER(G30))-1 -> 0
A31: 2) Комиссии - нетто | B31: Комиссионный доход | C31: РКО ЮЛ | D31: ЮЛ | E31: RUB | F31: ‭Комиссия за перевод средств ЮР.ЛИЦ, инв. вал‬ | G31: 8963055.7 | H31: 45658 | J31: Учетные данные | K31: Доход | L31: =(ISNUMBER(G31))-1 -> 0
A32: 7) Нетто эффект резервов на ОПУ | B32: Восстановление резервов | C32: =Data_BI!#REF! -> #REF! | D32: Прочее | E32: RUB | F32: ‭РВП по 611-П по другим активам и прочим операциям (47425)‬ | G32: 8740484.3 | H32: 45658 | I32: Согласно ст 292 НК РФ бан имеет право признавать только Резерв поод ссудную задолженность по 590-П | J32: Учетные данные | K32: Резервы | L32: =(ISNUMBER(G32))-1 -> 0
A33: 3) FX | B33: Безнал | C33: Доход безнал | D33: Прочее | E33: AED | G33: 7527124.1 | H33: 45658 | J33: Учетные данные | K33: Доход | L33: =(ISNUMBER(G33))-1 -> 0
A34: 2) Комиссии - нетто | B34: Комиссионный доход | C34: РКО ФЛ | D34: ФЛ | E34: RUB | F34: ‭Комиссия за перевод средств со счетов ФИЗ.ЛИЦ в ин.валюте‬ | G34: 7286208.5 | H34: 45658 | J34: Учетные данные | K34: Доход | L34: =(ISNUMBER(G34))-1 -> 0
A35: 2) Комиссии - нетто | B35: Комиссионный доход | C35: РКО ЮЛ | D35: ЮЛ | E35: RUB | F35: ‭Комиссия за валютный контроль ЮР.ЛИЦ в рублях облаг.НДС‬ | G35: 7227344.6 | H35: 45658 | J35: Учетные данные | K35: Доход | L35: =(ISNUMBER(G35))-1 -> 0
A36: 7) Нетто эффект резервов на ОПУ | B36: Восстановление резервов | C36: =Data_BI!#REF! -> #REF! | D36: Прочее | E36: RUB | F36: ‭Доходы от восстановления оценочных резервов по облигациям прочих резидентов‬ | G36: 6526218.4 | H36: 45658 | J36: Учетные данные | K36: Резервы | L36: =(ISNUMBER(G36))-1 -> 0
A37: 2) Комиссии - нетто | B37: Комиссионный доход | C37: РКО ЮЛ | D37: ЮЛ | E37: RUB | F37: ‭Комиссия за пакет обслуживания ЮР. ЛИЦ.‬ | G37: 5530150 | H37: 45658 | J37: Учетные данные | K37: Доход | L37: =(ISNUMBER(G37))-1 -> 0
A38: 7) Нетто эффект резервов на ОПУ | B38: Восстановление резервов | C38: =Data_BI!#REF! -> #REF! | D38: ЮЛ | E38: RUB | F38: ‭Доходы от создания оценочных резервов по кредитам юр. лиц резидентов‬ | G38: 5457123.9 | H38: 45658 | J38: Учетные данные | K38: Резервы | L38: =(ISNUMBER(G38))-1 -> 0
A39: 5) Доходы от участия в капитале | B39: Доходы от участия в капитале | D39: Прочее | E39: RUB | F39: ‭Дивиденды от вложений в акции организаций - резидентов‬ | G39: 5312300 | H39: 45658 | J39: Учетные данные | K39: Доход | L39: =(ISNUMBER(G39))-1 -> 0
A40: 1) ЧПД | B40: Процентный доход | C40: Проценты по кредитам ЮЛ/МБК | D40: Прочее | E40: RUB | F40: ‭Проценты по кредитам, предоставленным негосударственным финансовым организациям‬ | G40: 5246340.3 | H40: 45658 | J40: Учетные данные | K40: Доход | L40: =(ISNUMBER(G40))-1 -> 0
...

Sheet Лист4
A1: Тип проверки | B1: Наименование поля | C1: Пример данных | D1: Примечания
A2: Проверка по справочнику | B2: Название | C2: 1) ЧПД
A3: Проверка по справочнику | B3: Тип | C3: Процентный доход
A4: Проверка по справочнику | B4: 2уровень | C4: % по корсчетам в банках-нерезидентах
A5: Проверка по справочнику | B5: Ф/Ю | C5: ФЛ, ЮЛ, ИП | D5: Актуализировать данные
A6: Без проверки | B6: Расшифровка | C6: # | D6: Актуализировать данные
A7: Не нужно | B7: Название счета | C7: ‭% по корсчетам в банках- нерезидентах в иностранных валютах‬ | D7: Кажется тут лежат данные из расшифровки
A8: Проверка тип данных и заполненность | B8: Сумма | C8: 99411.47 | D8: Проверить пустые значения ( почти 1000 строк)
A9: Не нужно | B9: Сумма_модуль | C9: =IFERROR(IMABS([1]Data_BI!C$7),0) -> 0
A10: Проверка тип данных и заполненность | B10: Месяц | C10: Январь | D10: Отдавать в формате YYYY-MM-DD
A11: Не нужно | B11: Счет | C11: 7.060181e+19
A12: Не нужно | B12: Наименование клиента | C12: ‭Общество с ограниченной ответственностью "Цифра банк"‬
A13: Не нужно | B13: Код страны | C13: RU
A14: Без проверки | B14: Комментарии | C14: - | D14: Обединить с еще одним полем Комментарии, отдавать все в одном
A15: Проверка по справочнику | B15: УК | C15: Учетные данные
A16: Проверка по справочнику | B16: Группа | C16: Доход/Расход/Резервы | D16: Резервы
A17: Объединить с Комметарии | B17: Комментарии | C17: - | D17: Обединить с еще одним полем Комментарии, отдавать все в одном
A18: Добавить поле | B18: Код валюты | C18: RUB/USD/KZT … | D18: Мне кажется, он уже где-то есть. Просто нужно перенести в правильный столбец. А то он то ли в расшифровке лежит, код валюты, то ли еще где-то. То ли в наименовании счета.
A19: Добавить поле | B19: Страна резидентства (или хотя бы рез/нерез) | C19: RU/KZ/AM/KG | Резидент/Нерезидент | D19: Если нет возможности отдавать страну резидентство, достаточно просто резидент, не резидент.
A20: Добавить поле | B20: Тип деятельности | C20: Операционная/Инвестиционная/Переоценка | D20: Если есть такая возможность
A21: Добавить поле | B21: EBITDA | C21: true/false | D21: Отметить поля, которые входят в расчет ебитды, можно, наверное, без него, если согласовать четкий список параметров по которым я сам мог бы посчитать ебитду
